#VRML_SIM R2024a utf8

EXTERNPROTO "https://raw.githubusercontent.com/cyberbotics/webots/db8dbbd4f9da6beed4825283646a27bf53941176/projects/objects/floors/protos/Floor.proto"
EXTERNPROTO "https://raw.githubusercontent.com/cyberbotics/webots/db8dbbd4f9da6beed4825283646a27bf53941176/projects/objects/backgrounds/protos/TexturedBackground.proto"
EXTERNPROTO "https://raw.githubusercontent.com/cyberbotics/webots/db8dbbd4f9da6beed4825283646a27bf53941176/projects/objects/backgrounds/protos/TexturedBackgroundLight.proto"

WorldInfo {
  basicTimeStep 5
  contactProperties [
    ContactProperties {
      maxContactJoints 300
    }
  ]
}
Viewpoint {
  orientation -0.2425549506616542 0.002425661307581627 0.9701346360566369 3.122190608583309
  position 2.0989994014503095 0.7187924321441413 1.2103864306177061
  follow "Cury"
}
Robot {
  translation 0.025817514576127153 0.2939132827949469 0.6999674330775139
  rotation 0.999991957513211 0.004010596848405588 -4.67075489147289e-06 -3.1265383824254758
  children [
    Shape {
      appearance DEF body_material PBRAppearance {
        baseColor 0.898039 0.917647 0.929412
        roughness 1
        metalness 0
      }
      geometry DEF body Mesh {
        url [
          "meshes//body.STL"
        ]
      }
    }
    HingeJoint {
      jointParameters HingeJointParameters {
        position -0.782952322139691
        axis -1 0 0
        anchor 0.0105 0.35039 0.3717
      }
      device [
        PositionSensor {
          name "shank_joint_sensor"
        }
      ]
      endPoint Solid {
        translation 0.0105 0.35039 0.3717
        rotation 1 0 0 0.36408232214001995
        children [
          Shape {
            appearance DEF shank_material PBRAppearance {
              baseColor 0.498039 0.498039 0.498039
              roughness 1
              metalness 0
            }
            geometry DEF shank Mesh {
              url [
                "meshes//shank.STL"
              ]
            }
          }
          HingeJoint {
            jointParameters HingeJointParameters {
              position 0.19950401253535383
              axis -1 0 4e-06
              anchor -0.0235 0.029501 0.074362
            }
            device [
              PositionSensor {
                name "knee_joint_sensor"
              }
            ]
            endPoint Solid {
              translation -0.0235 0.029501 0.074362
              rotation -0.09909651230807935 0.9901312274015303 -0.09909608353872293 1.5807176289403602
              children [
                Shape {
                  appearance DEF knee_material PBRAppearance {
                    baseColor 0.898039 0.917647 0.929412
                    roughness 1
                    metalness 0
                  }
                  geometry DEF knee Mesh {
                    url [
                      "meshes//knee.STL"
                    ]
                  }
                }
                HingeJoint {
                  jointParameters HingeJointParameters {
                    position -0.13924640659533669
                    axis 0 0 1
                    anchor 0.109166 0.087619 -0.01075
                  }
                  device [
                    PositionSensor {
                      name "Joint_knee_link2_1_sensor"
                    }
                  ]
                  endPoint SolidReference {
                    solidName "shank_link_1_1"
                  }
                }
              ]
              name "knee"
              boundingObject USE knee
              physics Physics {
                density -1
                mass 0.168966
                centerOfMass [
                  0.050744 0.040728 0.0235
                ]
                inertiaMatrix [
                  0.0001836537 0.0002740295 0.0004354961
                  -0.0002038709 3.902577e-08 -4.862296e-08
                ]
              }
            }
          }
        ]
        name "shank"
        boundingObject USE shank
        physics Physics {
          density -1
          mass 0.836251
          centerOfMass [
            -9e-06 -0.023421 0.172151
          ]
          inertiaMatrix [
            0.007643359 0.00677757 0.00114458
            4.021087e-07 -7.247211e-07 0.002155519
          ]
        }
      }
    }
    HingeJoint {
      jointParameters HingeJointParameters {
        position -0.14098071837589338
        axis -1 0 0
        anchor -0.07 0.31937 0.15219
      }
      device [
        PositionSensor {
          name "motor_shank_joint_sensor"
        }
      ]
      endPoint Solid {
        translation -0.07 0.31937 0.15219
        rotation -1 0 0 0.2778892816240338
        children [
          Shape {
            appearance DEF motor_shank_material PBRAppearance {
              baseColor 0.898039 0.917647 0.929412
              roughness 1
              metalness 0
            }
            geometry DEF motor_shank Mesh {
              url [
                "meshes//motor_shank.STL"
              ]
            }
          }
          SliderJoint {
            jointParameters JointParameters {
              position 0.06058443335470197
              axis 0 0.300452 0.953797
              minStop -0.08
              maxStop 0.12
            }
            device [
              LinearMotor {
                name "screw_shank_joint"
                minPosition -0.08
                maxPosition 0.12
                maxForce 1000000
              }
              PositionSensor {
                name "screw_shank_joint_sensor"
              }
            ]
            endPoint Solid {
              translation 0.080508 0.02841971306435381 0.09027624726958539
              rotation -0.15026604111332043 0.9771592673542323 -0.15026604111332043 1.5939
              children [
                Shape {
                  appearance DEF screw_shank_material PBRAppearance {
                    baseColor 0.615686 0.643137 0.67451
                    roughness 1
                    metalness 0
                  }
                  geometry DEF screw_shank Mesh {
                    url [
                      "meshes//screw_shank.STL"
                    ]
                  }
                }
                HingeJoint {
                  jointParameters HingeJointParameters {
                    position -0.3032213914783907
                    axis 0 0 -1
                    anchor -0.152918 1.8e-05 -0.034258
                  }
                  device [
                    PositionSensor {
                      name "Joint_screw_shank_link2_1_sensor"
                    }
                  ]
                  endPoint SolidReference {
                    solidName "shank_link_1_1"
                  }
                }
              ]
              name "screw_shank"
              boundingObject USE screw_shank
              physics Physics {
                density -1
                mass 0.412508
                centerOfMass [
                  -0.004694 1.6e-05 -7e-06
                ]
                inertiaMatrix [
                  1.409353e-05 0.002013039 0.002013776
                  1.675319e-08 -9.998008e-08 -3.14569e-09
                ]
              }
            }
          }
        ]
        name "motor_shank"
        boundingObject USE motor_shank
        physics Physics {
          density -1
          mass 1.160888
          centerOfMass [
            0.0805 0.000763 0.002422
          ]
          inertiaMatrix [
            0.00184164 0.002517725 0.003849238
            1.949652e-06 -6.141524e-07 0.0004656397
          ]
        }
      }
    }
    HingeJoint {
      jointParameters HingeJointParameters {
        position 0.44420187971142766
        axis 1 -7e-06 0
        anchor 0.0105 0.30247 0.3524
      }
      device [
        PositionSensor {
          name "shank_link_1_1_joint_sensor"
        }
      ]
      endPoint Solid {
        translation 0.0105 0.30247 0.3524
        rotation 4.0740554891556765e-06 0.9999199274907102 0.012654587720469223 3.141592712646716
        children [
          Shape {
            appearance DEF shank_link_1_1_material PBRAppearance {
              baseColor 0.898039 0.917647 0.929412
              roughness 1
              metalness 0
            }
            geometry DEF shank_link_1_1 Mesh {
              url [
                "meshes//shank_link_1_1.STL"
              ]
            }
          }
        ]
        name "shank_link_1_1"
        boundingObject USE shank_link_1_1
        physics Physics {
          density -1
          mass 0.111289
          centerOfMass [
            -3.7e-05 0.10328 0.011994
          ]
          inertiaMatrix [
            0.0002851563 4.091473e-05 0.0002767847
            -4.210439e-07 -4.685942e-08 3.953451e-05
          ]
        }
      }
    }
    HingeJoint {
      jointParameters HingeJointParameters {
        position 0.0033416611590373797
        anchor 0.0905 0.13244 0.27812
      }
      device [
        PositionSensor {
          name "motor_hip_joint_sensor"
        }
      ]
      endPoint Solid {
        translation 0.0905 0.13244 0.27812
        rotation -1 0 0 0.4155283388409639
        children [
          Shape {
            appearance DEF motor_hip_material PBRAppearance {
              baseColor 0.776471 0.756863 0.737255
              roughness 1
              metalness 0
            }
            geometry DEF motor_hip Mesh {
              url [
                "meshes//motor_hip.STL"
              ]
            }
          }
          SliderJoint {
            jointParameters JointParameters {
              position 0.004432340756892156
              axis 0 0.355058 0.934844
              minStop -0.08
              maxStop 0.06
            }
            device [
              LinearMotor {
                name "screw_hip_joint"
                minPosition -0.08
                maxPosition 0.06
                maxForce 1000000
              }
              PositionSensor {
                name "screw_hip_joint_sensor"
              }
            ]
            endPoint Solid {
              translation -0.080484 0.01006773844757377 0.026537548223906103
              rotation -0.17762990566469 -0.9679334859519565 0.17762990566469 1.603382
              children [
                Shape {
                  appearance DEF screw_hip_material PBRAppearance {
                    baseColor 0.615686 0.643137 0.67451
                    roughness 1
                    metalness 0
                  }
                  geometry DEF screw_hip Mesh {
                    url [
                      "meshes//screw_hip.STL"
                    ]
                  }
                }
                HingeJoint {
                  jointParameters HingeJointParameters {
                    position -0.026482319424791876
                    axis 0 0 -1
                    anchor -0.155582 1.1e-05 -0.034234
                  }
                  device [
                    PositionSensor {
                      name "Joint_screw_hip_link2_2_sensor"
                    }
                  ]
                  endPoint SolidReference {
                    solidName "hip_link_1_2"
                  }
                }
              ]
              name "screw_hip"
              boundingObject USE screw_hip
              physics Physics {
                density -1
                mass 0.412508
                centerOfMass [
                  -0.006493 1e-05 1.4e-05
                ]
                inertiaMatrix [
                  1.409353e-05 0.002013034 0.002013779
                  3.933427e-08 -9.336841e-08 4.149733e-09
                ]
              }
            }
          }
        ]
        name "motor_hip"
        boundingObject USE motor_hip
        physics Physics {
          density -1
          mass 1.160888
          centerOfMass [
            -0.0805 -0.000902 -0.002374
          ]
          inertiaMatrix [
            0.00184164 0.002575902 0.003791061
            -1.910901e-06 7.257992e-07 0.0005393508
          ]
        }
      }
    }
    HingeJoint {
      jointParameters HingeJointParameters {
        position -0.010847753744127074
        axis 1 0 -1e-06
        anchor 0.01 0.10142 0.05862
      }
      device [
        PositionSensor {
          name "Hip_Joint_sensor"
        }
      ]
      endPoint Solid {
        translation 0.009999360717175413 0.1015544846674416 0.05808620044258489
        rotation -0.20853298301468068 0.9555247841764483 -0.208533886501813 1.616282139919569
        children [
          Solid {
            translation 0.0721221 0.0099209 0
            rotation 0 0 1 0.415
            children [
              Shape {
                appearance PBRAppearance {
                  transparency 1
                }
              }
              GPS {
              }
              SliderJoint {
                jointParameters JointParameters {
                  position 0.5137410041419616
                  axis 1 0 0
                  minStop -1
                  maxStop 1
                }
                device [
                  Brake {
                  }
                ]
                endPoint Solid {
                  translation -0.4667729250475161 -1.9103135579852504 -0.0019373941095941552
                  rotation 0.1808385568263801 -0.1930560517479635 -0.964378959355937 0.00029262100957649136
                  children [
                    DEF SUPPORT Shape {
                      appearance PBRAppearance {
                        transparency 1
                        metalness 0
                      }
                      geometry Box {
                        size 0.5 3 1
                      }
                      castShadows FALSE
                    }
                  ]
                  boundingObject USE SUPPORT
                  physics Physics {
                    density -1
                    mass 95
                  }
                  radarCrossSection 1
                }
              }
              DEF SUPPORT1 Shape {
                appearance PBRAppearance {
                  metalness 0
                }
                geometry Box {
                  size 0.01 0.08 0.01
                }
              }
            ]
            boundingObject USE SUPPORT1
            physics Physics {
              density -1
              mass 0.01
            }
          }
          Shape {
            appearance DEF Hip__material PBRAppearance {
              baseColor 0.898039 0.917647 0.929412
              roughness 1
              metalness 0
            }
            geometry DEF Hip_ Mesh {
              url [
                "meshes//Hip .STL"
              ]
            }
          }
          HingeJoint {
            jointParameters HingeJointParameters {
              position -0.008007174700357483
              axis 0 0 1
              anchor 0.044142 -0.067975 -0.0025
            }
            device [
              PositionSensor {
                name "joint_ass_sensor"
              }
            ]
            endPoint Solid {
              translation 0.044142 -0.067975 -0.0025
              rotation 0 0 -1 0.008007174700375343
              children [
                Shape {
                  appearance DEF ass_material PBRAppearance {
                    baseColor 0.898039 0.917647 0.929412
                    roughness 1
                    metalness 0
                  }
                  geometry DEF ass Mesh {
                    url [
                      "meshes//ass.STL"
                    ]
                  }
                }
                HingeJoint {
                  jointParameters HingeJointParameters {
                    position -0.004285988348998525
                    axis 0 0 1
                    anchor -0.13423 -0.039707 0.03675
                  }
                  device [
                    PositionSensor {
                      name "Joint_ass_hip_link2_2_sensor"
                    }
                  ]
                  endPoint SolidReference {
                    solidName "hip_link_1_2"
                  }
                }
              ]
              name "ass"
              boundingObject USE ass
              physics Physics {
                density -1
                mass 0.168966
                centerOfMass [
                  -0.062394 -0.018457 0.0025
                ]
                inertiaMatrix [
                  5.362724e-05 0.0004040559 0.0004354961
                  -0.0001136011 -1.768546e-08 5.978653e-08
                ]
              }
            }
          }
        ]
        name "Hip "
        boundingObject USE Hip_
        physics Physics {
          density -1
          mass 0.276023
          centerOfMass [
            0.031473 -0.016572 8.6e-05
          ]
          inertiaMatrix [
            0.0003779971 0.0002686291 0.0006282622
            0.0001192141 -3.02343e-07 1.226949e-06
          ]
        }
      }
    }
    HingeJoint {
      jointParameters HingeJointParameters {
        position 0.023140731497587892
        axis -1 0 0
        anchor 0.01 0.14935 0.077917
      }
      device [
        PositionSensor {
          name "hip_link_1_2_joint_sensor"
        }
      ]
      endPoint Solid {
        translation 0.01 0.14935 0.077917
        rotation -1 0 0 0.4420107314975835
        children [
          Shape {
            appearance DEF hip_link_1_2_material PBRAppearance {
              baseColor 0.898039 0.917647 0.929412
              roughness 1
              metalness 0
            }
            geometry DEF hip_link_1_2 Mesh {
              url [
                "meshes//hip_link_1_2.STL"
              ]
            }
          }
        ]
        name "hip_link_1_2"
        boundingObject USE hip_link_1_2
        physics Physics {
          density -1
          mass 0.11129
          centerOfMass [
            3.7e-05 -0.092028 0.04839
          ]
          inertiaMatrix [
            0.0002851565 4.494651e-05 0.0002727509
            -3.759739e-07 1.953739e-07 4.99796e-05
          ]
        }
      }
    }
  ]
  name "Cury"
  boundingObject USE body
  physics Physics {
    density -1
    mass 2.275612
    centerOfMass [
      0.01059 0.225901 0.21515
    ]
    inertiaMatrix [
      0.03307588 0.01873076 0.01451556
      -4.553757e-08 -1.059717e-07 -0.01343235
    ]
  }
  controller "my_controller"
}
Floor {
}
TexturedBackground {
}
TexturedBackgroundLight {
}
