#VRML_SIM R2024a utf8

EXTERNPROTO "https://raw.githubusercontent.com/cyberbotics/webots/db8dbbd4f9da6beed4825283646a27bf53941176/projects/objects/floors/protos/Floor.proto"
EXTERNPROTO "https://raw.githubusercontent.com/cyberbotics/webots/db8dbbd4f9da6beed4825283646a27bf53941176/projects/objects/backgrounds/protos/TexturedBackground.proto"
EXTERNPROTO "https://raw.githubusercontent.com/cyberbotics/webots/db8dbbd4f9da6beed4825283646a27bf53941176/projects/objects/backgrounds/protos/TexturedBackgroundLight.proto"

WorldInfo {
  basicTimeStep 5
  contactProperties [
    ContactProperties {
      maxContactJoints 300
    }
  ]
}
Viewpoint {
  orientation -0.22309682498068029 -0.008928600922140005 0.9747553984303512 3.2195758710315623
  position 1.9758720118862834 0.370469306718256 1.6051883607745547
  follow "Cury"
}
Robot {
  translation 0.02579898694355945 0.29430664820357677 0.6916969089094371
  rotation 0.9999919649845169 0.004008633091510421 2.8760080114458815e-05 3.140711742397115
  children [
    Shape {
      appearance DEF body_material PBRAppearance {
        baseColor 0.898039 0.917647 0.929412
        roughness 1
        metalness 0
      }
      geometry DEF body Mesh {
        url [
          "meshes//body.STL"
        ]
      }
    }
    HingeJoint {
      jointParameters HingeJointParameters {
        position -0.8097706223399775
        axis -1 0 0
        anchor 0.0105 0.35039 0.3717
      }
      device [
        PositionSensor {
          name "shank_joint_sensor"
        }
      ]
      endPoint Solid {
        translation 0.0105 0.35039 0.3717
        rotation 1 0 0 0.3909006223403074
        children [
          Shape {
            appearance DEF shank_material PBRAppearance {
              baseColor 0.498039 0.498039 0.498039
              roughness 1
              metalness 0
            }
            geometry DEF shank Mesh {
              url [
                "meshes//shank.STL"
              ]
            }
          }
          HingeJoint {
            jointParameters HingeJointParameters {
              position 0.21671316950501576
              axis -1 0 4e-06
              anchor -0.0235 0.029501 0.074362
            }
            device [
              PositionSensor {
                name "knee_joint_sensor"
              }
            ]
            endPoint Solid {
              translation -0.0235 0.029501 0.074362
              rotation -0.10751781334078722 0.988372368930147 -0.10751734813426732 1.582495493722758
              children [
                Shape {
                  appearance DEF knee_material PBRAppearance {
                    baseColor 0.898039 0.917647 0.929412
                    roughness 1
                    metalness 0
                  }
                  geometry DEF knee Mesh {
                    url [
                      "meshes//knee.STL"
                    ]
                  }
                }
                HingeJoint {
                  jointParameters HingeJointParameters {
                    position -0.14694284354362025
                    axis 0 0 1
                    anchor 0.109166 0.087619 -0.01075
                  }
                  device [
                    PositionSensor {
                      name "Joint_knee_link2_1_sensor"
                    }
                  ]
                  endPoint SolidReference {
                    solidName "shank_link_1_1"
                  }
                }
              ]
              name "knee"
              boundingObject USE knee
              physics Physics {
                density -1
                mass 0.168966
                centerOfMass [
                  0.050744 0.040728 0.0235
                ]
                inertiaMatrix [
                  0.0001836537 0.0002740295 0.0004354961
                  -0.0002038709 3.902577e-08 -4.862296e-08
                ]
              }
            }
          }
        ]
        name "shank"
        boundingObject USE shank
        physics Physics {
          density -1
          mass 0.836251
          centerOfMass [
            -9e-06 -0.023421 0.172151
          ]
          inertiaMatrix [
            0.007643359 0.00677757 0.00114458
            4.021087e-07 -7.247211e-07 0.002155519
          ]
        }
      }
    }
    HingeJoint {
      jointParameters HingeJointParameters {
        position -0.14286454458889206
        axis -1 0 0
        anchor -0.07 0.31937 0.15219
      }
      device [
        PositionSensor {
          name "motor_shank_joint_sensor"
        }
      ]
      endPoint Solid {
        translation -0.07 0.31937 0.15219
        rotation -1 0 0 0.27600545541103305
        children [
          Shape {
            appearance DEF motor_shank_material PBRAppearance {
              baseColor 0.898039 0.917647 0.929412
              roughness 1
              metalness 0
            }
            geometry DEF motor_shank Mesh {
              url [
                "meshes//motor_shank.STL"
              ]
            }
          }
          SliderJoint {
            jointParameters JointParameters {
              position 0.06005097325871181
              axis 0 0.300452 0.953797
              minStop -0.08
              maxStop 0.12
            }
            device [
              LinearMotor {
                name "screw_shank_joint"
                minPosition -0.08
                maxPosition 0.12
                maxForce 1000000
              }
              PositionSensor {
                name "screw_shank_joint_sensor"
              }
            ]
            endPoint Solid {
              translation 0.080508 0.028259433921331376 0.08976743466132393
              rotation -0.15026604111332043 0.9771592673542323 -0.15026604111332043 1.5939
              children [
                Shape {
                  appearance DEF screw_shank_material PBRAppearance {
                    baseColor 0.615686 0.643137 0.67451
                    roughness 1
                    metalness 0
                  }
                  geometry DEF screw_shank Mesh {
                    url [
                      "meshes//screw_shank.STL"
                    ]
                  }
                }
                HingeJoint {
                  jointParameters HingeJointParameters {
                    position -0.30325038310621627
                    axis 0 0 -1
                    anchor -0.152918 1.8e-05 -0.034258
                  }
                  device [
                    PositionSensor {
                      name "Joint_screw_shank_link2_1_sensor"
                    }
                  ]
                  endPoint SolidReference {
                    solidName "shank_link_1_1"
                  }
                }
              ]
              name "screw_shank"
              boundingObject USE screw_shank
              physics Physics {
                density -1
                mass 0.412508
                centerOfMass [
                  -0.004694 1.6e-05 -7e-06
                ]
                inertiaMatrix [
                  1.409353e-05 0.002013039 0.002013776
                  1.675319e-08 -9.998008e-08 -3.14569e-09
                ]
              }
            }
          }
        ]
        name "motor_shank"
        boundingObject USE motor_shank
        physics Physics {
          density -1
          mass 1.160888
          centerOfMass [
            0.0805 0.000763 0.002422
          ]
          inertiaMatrix [
            0.00184164 0.002517725 0.003849238
            1.949652e-06 -6.141524e-07 0.0004656397
          ]
        }
      }
    }
    HingeJoint {
      jointParameters HingeJointParameters {
        position 0.446114601880936
        axis 1 -7e-06 0
        anchor 0.0105 0.30247 0.3524
      }
      device [
        PositionSensor {
          name "shank_link_1_1_joint_sensor"
        }
      ]
      endPoint Solid {
        translation 0.0105 0.30247 0.3524
        rotation 4.073940669719738e-06 0.9999073678607069 0.013610866294111023 3.141592707051243
        children [
          Shape {
            appearance DEF shank_link_1_1_material PBRAppearance {
              baseColor 0.898039 0.917647 0.929412
              roughness 1
              metalness 0
            }
            geometry DEF shank_link_1_1 Mesh {
              url [
                "meshes//shank_link_1_1.STL"
              ]
            }
          }
        ]
        name "shank_link_1_1"
        boundingObject USE shank_link_1_1
        physics Physics {
          density -1
          mass 0.111289
          centerOfMass [
            -3.7e-05 0.10328 0.011994
          ]
          inertiaMatrix [
            0.0002851563 4.091473e-05 0.0002767847
            -4.210439e-07 -4.685942e-08 3.953451e-05
          ]
        }
      }
    }
    HingeJoint {
      jointParameters HingeJointParameters {
        position 0.004706417469656098
        anchor 0.0905 0.13244 0.27812
      }
      device [
        PositionSensor {
          name "motor_hip_joint_sensor"
        }
      ]
      endPoint Solid {
        translation 0.0905 0.13244 0.27812
        rotation -1 0 0 0.4141635825303394
        children [
          Shape {
            appearance DEF motor_hip_material PBRAppearance {
              baseColor 0.776471 0.756863 0.737255
              roughness 1
              metalness 0
            }
            geometry DEF motor_hip Mesh {
              url [
                "meshes//motor_hip.STL"
              ]
            }
          }
          SliderJoint {
            jointParameters JointParameters {
              position 0.0046875033343179925
              axis 0 0.355058 0.934844
              minStop -0.08
              maxStop 0.06
            }
            device [
              LinearMotor {
                name "screw_hip_joint"
                minPosition -0.08
                maxPosition 0.07
                maxForce 1000000
              }
              PositionSensor {
                name "screw_hip_joint_sensor"
              }
            ]
            endPoint Solid {
              translation -0.080484 0.010158335985195995 0.026776085489538512
              rotation -0.17762990566469 -0.9679334859519565 0.17762990566469 1.603382
              children [
                Shape {
                  appearance DEF screw_hip_material PBRAppearance {
                    baseColor 0.615686 0.643137 0.67451
                    roughness 1
                    metalness 0
                  }
                  geometry DEF screw_hip Mesh {
                    url [
                      "meshes//screw_hip.STL"
                    ]
                  }
                }
                HingeJoint {
                  jointParameters HingeJointParameters {
                    position -0.026393898552115477
                    axis 0 0 -1
                    anchor -0.155582 1.1e-05 -0.034234
                  }
                  device [
                    PositionSensor {
                      name "Joint_screw_hip_link2_2_sensor"
                    }
                  ]
                  endPoint SolidReference {
                    solidName "hip_link_1_2"
                  }
                }
              ]
              name "screw_hip"
              boundingObject USE screw_hip
              physics Physics {
                density -1
                mass 0.412508
                centerOfMass [
                  -0.006493 1e-05 1.4e-05
                ]
                inertiaMatrix [
                  1.409353e-05 0.002013034 0.002013779
                  3.933427e-08 -9.336841e-08 4.149733e-09
                ]
              }
            }
          }
        ]
        name "motor_hip"
        boundingObject USE motor_hip
        physics Physics {
          density -1
          mass 1.160888
          centerOfMass [
            -0.0805 -0.000902 -0.002374
          ]
          inertiaMatrix [
            0.00184164 0.002575902 0.003791061
            -1.910901e-06 7.257992e-07 0.0005393508
          ]
        }
      }
    }
    HingeJoint {
      jointParameters HingeJointParameters {
        position 0.005289315839675686
        axis 1 0 -1e-06
        anchor 0.01 0.10142 0.05862
      }
      device [
        PositionSensor {
          name "Hip_Joint_sensor"
        }
      ]
      endPoint Solid {
        translation 0.009999360719415009 0.10156308074434457 0.05808844003736727
        rotation -0.2011345502432717 0.9586915232218945 -0.20113541707248028 1.6129766620861803
        children [
          Solid {
            translation 0.0721221 0.0099209 0
            rotation 0 0 1 0.415
            children [
              Shape {
                appearance PBRAppearance {
                  transparency 1
                }
              }
              GPS {
              }
              SliderJoint {
                jointParameters JointParameters {
                  position 0.5202438355967852
                  axis 1 0 0
                  minStop -1
                  maxStop 1
                }
                device [
                  Brake {
                  }
                ]
                endPoint Solid {
                  translation -0.46027009359269244 -1.9103135579852504 -0.0019373941095941552
                  rotation 0.1808385568263801 -0.1930560517479635 -0.964378959355937 0.00029262100957649136
                  children [
                    DEF SUPPORT Shape {
                      appearance PBRAppearance {
                        transparency 1
                        metalness 0
                      }
                      geometry Box {
                        size 0.5 3 1
                      }
                      castShadows FALSE
                    }
                  ]
                  boundingObject USE SUPPORT
                  physics Physics {
                    density -1
                    mass 95
                  }
                  radarCrossSection 1
                }
              }
              DEF SUPPORT1 Shape {
                appearance PBRAppearance {
                  metalness 0
                }
                geometry Box {
                  size 0.01 0.08 0.01
                }
              }
            ]
            boundingObject USE SUPPORT1
            physics Physics {
              density -1
              mass 0.01
            }
          }
          Shape {
            appearance DEF Hip__material PBRAppearance {
              baseColor 0.898039 0.917647 0.929412
              roughness 1
              metalness 0
            }
            geometry DEF Hip_ Mesh {
              url [
                "meshes//Hip .STL"
              ]
            }
          }
          HingeJoint {
            jointParameters HingeJointParameters {
              position -0.02218308961915673
              axis 0 0 1
              anchor 0.044142 -0.067975 -0.0025
            }
            device [
              PositionSensor {
                name "joint_ass_sensor"
              }
            ]
            endPoint Solid {
              translation 0.044142 -0.067975 -0.0025
              rotation 0 0 -1 0.022183089619162728
              children [
                Shape {
                  appearance DEF ass_material PBRAppearance {
                    baseColor 0.898039 0.917647 0.929412
                    roughness 1
                    metalness 0
                  }
                  geometry DEF ass Mesh {
                    url [
                      "meshes//ass.STL"
                    ]
                  }
                }
                HingeJoint {
                  jointParameters HingeJointParameters {
                    position -0.0047939485588011175
                    axis 0 0 1
                    anchor -0.13423 -0.039707 0.03675
                  }
                  device [
                    PositionSensor {
                      name "Joint_ass_hip_link2_2_sensor"
                    }
                  ]
                  endPoint SolidReference {
                    solidName "hip_link_1_2"
                  }
                }
              ]
              name "ass"
              boundingObject USE ass
              physics Physics {
                density -1
                mass 0.168966
                centerOfMass [
                  -0.062394 -0.018457 0.0025
                ]
                inertiaMatrix [
                  5.362724e-05 0.0004040559 0.0004354961
                  -0.0001136011 -1.768546e-08 5.978653e-08
                ]
              }
            }
          }
        ]
        name "Hip "
        boundingObject USE Hip_
        physics Physics {
          density -1
          mass 0.276023
          centerOfMass [
            0.031473 -0.016572 8.6e-05
          ]
          inertiaMatrix [
            0.0003779971 0.0002686291 0.0006282622
            0.0001192141 -3.02343e-07 1.226949e-06
          ]
        }
      }
    }
    HingeJoint {
      jointParameters HingeJointParameters {
        position 0.021687483923760888
        axis -1 0 0
        anchor 0.01 0.14935 0.077917
      }
      device [
        PositionSensor {
          name "hip_link_1_2_joint_sensor"
        }
      ]
      endPoint Solid {
        translation 0.01 0.14935 0.077917
        rotation -1 0 0 0.44055748392375105
        children [
          Shape {
            appearance DEF hip_link_1_2_material PBRAppearance {
              baseColor 0.898039 0.917647 0.929412
              roughness 1
              metalness 0
            }
            geometry DEF hip_link_1_2 Mesh {
              url [
                "meshes//hip_link_1_2.STL"
              ]
            }
          }
        ]
        name "hip_link_1_2"
        boundingObject USE hip_link_1_2
        physics Physics {
          density -1
          mass 0.11129
          centerOfMass [
            3.7e-05 -0.092028 0.04839
          ]
          inertiaMatrix [
            0.0002851565 4.494651e-05 0.0002727509
            -3.759739e-07 1.953739e-07 4.99796e-05
          ]
        }
      }
    }
  ]
  name "Cury"
  boundingObject USE body
  physics Physics {
    density -1
    mass 2.275612
    centerOfMass [
      0.01059 0.225901 0.21515
    ]
    inertiaMatrix [
      0.03307588 0.01873076 0.01451556
      -4.553757e-08 -1.059717e-07 -0.01343235
    ]
  }
  controller "my_controller"
}
Floor {
}
TexturedBackground {
}
TexturedBackgroundLight {
}
